<?xml version="1.0" encoding="utf-8"?>
<!-- This URDF was automatically created by SolidWorks to URDF Exporter! Originally created by Stephen Brawner (brawner@gmail.com) 
     Commit Version: 1.6.0-1-g15f4949  Build Version: 1.6.7594.29634
     For more information, please see http://wiki.ros.org/sw_urdf_exporter -->
<robot
  name="flying_manipulator_arm">
  <link
    name="arm_base_link">
    <inertial>
      <origin
        xyz="6.8888E-08 0.0005198 -0.060933"
        rpy="0 0 0" />
      <mass
        value="0.23834" />
      <inertia
        ixx="0.00014646"
        ixy="-4.6203E-05"
        ixz="2.9588E-12"
        iyy="0.00021227"
        iyz="-5.2784E-06"
        izz="0.00027887" />
    </inertial>
    <visual>
      <origin
        xyz="0 0 0"
        rpy="0 0 0" />
      <geometry>
        <mesh
          filename="package://flying_manipulator_arm/meshes/arm_base_link.STL" />
      </geometry>
      <material
        name="">
        <color
          rgba="0.64706 0.51765 0 1" />
      </material>
    </visual>
    <collision>
      <origin
        xyz="0 0 0"
        rpy="0 0 0" />
      <geometry>
        <mesh
          filename="package://flying_manipulator_arm/meshes/arm_base_link.STL" />
      </geometry>
    </collision>
  </link>
  <link
    name="arm_link_1">
    <inertial>
      <origin
        xyz="-0.0071984 5.2965E-07 -0.040115"
        rpy="0 0 0" />
      <mass
        value="0.087666" />
      <inertia
        ixx="3.1627E-05"
        ixy="-3.6677E-10"
        ixz="5.4309E-06"
        iyy="3.0921E-05"
        iyz="-2.1161E-09"
        izz="3.7509E-05" />
    </inertial>
    <visual>
      <origin
        xyz="0 0 0"
        rpy="0 0 0" />
      <geometry>
        <mesh
          filename="package://flying_manipulator_arm/meshes/arm_link_1.STL" />
      </geometry>
      <material
        name="">
        <color
          rgba="0.89804 0.91765 0.92941 1" />
      </material>
    </visual>
    <collision>
      <origin
        xyz="0 0 0"
        rpy="0 0 0" />
      <geometry>
        <mesh
          filename="package://flying_manipulator_arm/meshes/arm_link_1.STL" />
      </geometry>
    </collision>
  </link>
  <joint
    name="arm_joint_1"
    type="revolute">
    <origin
      xyz="0 0.0895 0"
      rpy="2.4302 1.5708 0" />
    <parent
      link="arm_base_link" />
    <child
      link="arm_link_1" />
    <axis
      xyz="-1 0 0" />
    <limit
      lower="-3.14"
      upper="3.14"
      effort="100"
      velocity="100" />
  </joint>
  <link
    name="arm_link_2">
    <inertial>
      <origin
        xyz="-0.00072842 -0.00022202 0.02553"
        rpy="0 0 0" />
      <mass
        value="0.10559" />
      <inertia
        ixx="0.00010233"
        ixy="-5.0947E-08"
        ixz="-6.5487E-07"
        iyy="9.0284E-05"
        iyz="-8.153E-08"
        izz="1.8127E-05" />
    </inertial>
    <visual>
      <origin
        xyz="0 0 0"
        rpy="0 0 0" />
      <geometry>
        <mesh
          filename="package://flying_manipulator_arm/meshes/arm_link_2.STL" />
      </geometry>
      <material
        name="">
        <color
          rgba="0.89804 0.91765 0.92941 1" />
      </material>
    </visual>
    <collision>
      <origin
        xyz="0 0 0"
        rpy="0 0 0" />
      <geometry>
        <mesh
          filename="package://flying_manipulator_arm/meshes/arm_link_2.STL" />
      </geometry>
    </collision>
  </link>
  <joint
    name="arm_joint_2"
    type="revolute">
    <origin
      xyz="0 0 -0.14296"
      rpy="3.1416 0 3.1359" />
    <parent
      link="arm_link_1" />
    <child
      link="arm_link_2" />
    <axis
      xyz="0 0 1" />
    <limit
      lower="-3.14"
      upper="3.14"
      effort="100"
      velocity="100" />
  </joint>
  <link
    name="arm_link_3">
    <inertial>
      <origin
        xyz="-0.0074811 -0.0001625 -0.039025"
        rpy="0 0 0" />
      <mass
        value="0.086986" />
      <inertia
        ixx="3.031E-05"
        ixy="3.5519E-10"
        ixz="5.3565E-06"
        iyy="3.0859E-05"
        iyz="-1.6295E-08"
        izz="3.7684E-05" />
    </inertial>
    <visual>
      <origin
        xyz="0 0 0"
        rpy="0 0 0" />
      <geometry>
        <mesh
          filename="package://flying_manipulator_arm/meshes/arm_link_3.STL" />
      </geometry>
      <material
        name="">
        <color
          rgba="0.89804 0.91765 0.92941 1" />
      </material>
    </visual>
    <collision>
      <origin
        xyz="0 0 0"
        rpy="0 0 0" />
      <geometry>
        <mesh
          filename="package://flying_manipulator_arm/meshes/arm_link_3.STL" />
      </geometry>
    </collision>
  </link>
  <joint
    name="arm_joint_3"
    type="revolute">
    <origin
      xyz="0 0 0.069036"
      rpy="2.6943 0 0" />
    <parent
      link="arm_link_2" />
    <child
      link="arm_link_3" />
    <axis
      xyz="-1 0 0" />
    <limit
      lower="-3.14"
      upper="3.14"
      effort="100"
      velocity="100" />
  </joint>
  <link
    name="arm_link_4">
    <inertial>
      <origin
        xyz="0.00020523 -0.0029296 0.0079122"
        rpy="0 0 0" />
      <mass
        value="0.013253" />
      <inertia
        ixx="2.333E-06"
        ixy="-7.9684E-09"
        ixz="4.9095E-09"
        iyy="1.7076E-06"
        iyz="1.1168E-07"
        izz="3.0343E-06" />
    </inertial>
    <visual>
      <origin
        xyz="0 0 0"
        rpy="0 0 0" />
      <geometry>
        <mesh
          filename="package://flying_manipulator_arm/meshes/arm_link_4.STL" />
      </geometry>
      <material
        name="">
        <color
          rgba="1 1 1 1" />
      </material>
    </visual>
    <collision>
      <origin
        xyz="0 0 0"
        rpy="0 0 0" />
      <geometry>
        <mesh
          filename="package://flying_manipulator_arm/meshes/arm_link_4.STL" />
      </geometry>
    </collision>
  </link>
  <joint
    name="arm_joint_4"
    type="revolute">
    <origin
      xyz="0 0 -0.071693"
      rpy="3.1416 0 2.8331" />
    <parent
      link="arm_link_3" />
    <child
      link="arm_link_4" />
    <axis
      xyz="0 0 1" />
    <limit
      lower="-3.14"
      upper="3.14"
      effort="100"
      velocity="100" />
  </joint>
</robot>