<?xml version="1.0"?>
<robot xmlns:xacro="http://ros.org/wiki/xacro">
    <xacro:include filename="$(find le_arm)/urdf/le_arm.transmission.xacro" />
    <xacro:include filename="$(find le_arm)/urdf/le_arm_gripper.urdf.xacro" />
    <xacro:macro name="le_arm" params="parent *origin">  
        <joint name="arm_base_joint" type="fixed">
            <parent link="${parent}"/>
            <child link="arm_base_link"/>
            <xacro:insert_block name="origin"/>
        </joint>

        <link
            name="arm_base_link">
            <inertial>
            <origin
                xyz="6.8888E-08 0.0005198 -0.060933"
                rpy="0 0 0" />
            <mass
                value="0.23834" />
            <inertia
                ixx="0.00014646"
                ixy="-4.6203E-05"
                ixz="2.9588E-12"
                iyy="0.00021227"
                iyz="-5.2784E-06"
                izz="0.00027887" />
            </inertial>
            <visual>
            <origin
                xyz="0 0 0"
                rpy="0 0 0" />
            <geometry>
                <mesh
                filename="package://le_arm/meshes/arm/base_link.STL" />
            </geometry>
            <material
                name="">
                <color
                rgba="0.64706 0.51765 0 1" />
            </material>
            </visual>
            <collision>
            <origin
                xyz="0 0 0"
                rpy="0 0 0" />
            <geometry>
                <mesh
                filename="package://le_arm/meshes/arm/base_link.STL" />
            </geometry>
            </collision>
        </link>

        <gazebo reference="arm_base_link">
            <implicitSpringDamper>1</implicitSpringDamper>
            <mu1>100000</mu1>
            <mu2>100000</mu2>
            <kp>100000000.0</kp>
            <kd>1.0</kd>
        </gazebo> 

        <link
            name="shoulder_link">
            <inertial>
            <origin
                xyz="-0.0071984 5.2965E-07 -0.040115"
                rpy="0 0 0" />
            <mass
                value="0.087666" />
            <inertia
                ixx="3.1627E-05"
                ixy="-3.6677E-10"
                ixz="5.4309E-06"
                iyy="3.0921E-05"
                iyz="-2.1161E-09"
                izz="3.7509E-05" />
            </inertial>
            <visual>
            <origin
                xyz="0 0 0"
                rpy="0 0 0" />
            <geometry>
                <mesh
                filename="package://le_arm/meshes/arm/shoulder_link.STL" />
            </geometry>
            <material
                name="">
                <color
                rgba="0.89804 0.91765 0.92941 1" />
            </material>
            </visual>
            <collision>
            <origin
                xyz="0 0 0"
                rpy="0 0 0" />
            <geometry>
                <mesh
                filename="package://le_arm/meshes/arm/shoulder_link.STL" />
            </geometry>
            </collision>
        </link>

                
        <gazebo reference="shoulder_link">
            <implicitSpringDamper>1</implicitSpringDamper>
            <mu1>100000</mu1>
            <mu2>100000</mu2>
            <kp>100000000.0</kp>
            <kd>1.0</kd>
        </gazebo> 

        <joint
            name="shoulder_pan_joint"
            type="revolute">
            <origin
            xyz="0 0.0895 0"
            rpy="2.4302 1.5708 0" />
            <parent
            link="arm_base_link" />
            <child
            link="shoulder_link" />
            <axis
            xyz="-1 0 0" />
            <limit
            lower="-3.14"
            upper="3.14"
            effort="100"
            velocity="100" />
        </joint>
        <link
            name="upper_arm_link">
            <inertial>
            <origin
                xyz="-0.00072842 -0.00022202 0.02553"
                rpy="0 0 0" />
            <mass
                value="0.10559" />
            <inertia
                ixx="0.00010233"
                ixy="-5.0947E-08"
                ixz="-6.5487E-07"
                iyy="9.0284E-05"
                iyz="-8.153E-08"
                izz="1.8127E-05" />
            </inertial>
            <visual>
            <origin
                xyz="0 0 0"
                rpy="0 0 0" />
            <geometry>
                <mesh
                filename="package://le_arm/meshes/arm/upper_arm_link.STL" />
            </geometry>
            <material
                name="">
                <color
                rgba="0.89804 0.91765 0.92941 1" />
            </material>
            </visual>
            <collision>
            <origin
                xyz="0 0 0"
                rpy="0 0 0" />
            <geometry>
                <mesh
                filename="package://le_arm/meshes/arm/upper_arm_link.STL" />
            </geometry>
            </collision>
        </link>

        <gazebo reference="upper_arm_link">
            <implicitSpringDamper>1</implicitSpringDamper>
            <mu1>100000</mu1>
            <mu2>100000</mu2>
            <kp>100000000.0</kp>
            <kd>1.0</kd>
        </gazebo> 

        <joint
            name="shoulder_lift_joint"
            type="revolute">
            <origin
            xyz="0 0 -0.14296"
            rpy="3.1416 0 3.1359" />
            <parent
            link="shoulder_link" />
            <child
            link="upper_arm_link" />
            <axis
            xyz="0 0 1" />
            <limit
            lower="-3.14"
            upper="3.14"
            effort="100"
            velocity="100" />
        </joint>
        <link
            name="forearm_link">
            <inertial>
            <origin
                xyz="-0.0074811 -0.0001625 -0.039025"
                rpy="0 0 0" />
            <mass
                value="0.086986" />
            <inertia
                ixx="3.031E-05"
                ixy="3.5519E-10"
                ixz="5.3565E-06"
                iyy="3.0859E-05"
                iyz="-1.6295E-08"
                izz="3.7684E-05" />
            </inertial>
            <visual>
            <origin
                xyz="0 0 0"
                rpy="0 0 0" />
            <geometry>
                <mesh
                filename="package://le_arm/meshes/arm/forearm_link.STL" />
            </geometry>
            <material
                name="">
                <color
                rgba="0.89804 0.91765 0.92941 1" />
            </material>
            </visual>
            <collision>
            <origin
                xyz="0 0 0"
                rpy="0 0 0" />
            <geometry>
                <mesh
                filename="package://le_arm/meshes/arm/forearm_link.STL" />
            </geometry>
            </collision>
        </link>

        <gazebo reference="forearm_link">
            <implicitSpringDamper>1</implicitSpringDamper>
            <mu1>100000</mu1>
            <mu2>100000</mu2>
            <kp>100000000.0</kp>
            <kd>1.0</kd>
        </gazebo> 


        <joint
            name="elbow_joint"
            type="revolute">
            <origin
            xyz="0 0 0.069036"
            rpy="2.6943 0 0" />
            <parent
            link="upper_arm_link" />
            <child
            link="forearm_link" />
            <axis
            xyz="-1 0 0" />
            <limit
            lower="-3.14"
            upper="3.14"
            effort="100"
            velocity="100" />
        </joint>
        <link
            name="wrist_1_link">
            <inertial>
            <origin
                xyz="0.00020523 -0.0029296 0.0079122"
                rpy="0 0 0" />
            <mass
                value="0.013253" />
            <inertia
                ixx="2.333E-06"
                ixy="-7.9684E-09"
                ixz="4.9095E-09"
                iyy="1.7076E-06"
                iyz="1.1168E-07"
                izz="3.0343E-06" />
            </inertial>
            <visual>
            <origin
                xyz="0 0 0"
                rpy="0 0 0" />
            <geometry>
                <mesh
                filename="package://le_arm/meshes/arm/wrist_1_link.STL" />
            </geometry>
            <material
                name="">
                <color
                rgba="1 1 1 1" />
            </material>
            </visual>
            <collision>
            <origin
                xyz="0 0 0"
                rpy="0 0 0" />
            <geometry>
                <mesh
                filename="package://le_arm/meshes/arm/wrist_1_link.STL" />
            </geometry>
            </collision>
        </link>

         <gazebo reference="wrist_1_link">
            <implicitSpringDamper>1</implicitSpringDamper>
            <mu1>100000</mu1>
            <mu2>100000</mu2>
            <kp>100000000.0</kp>
            <kd>1.0</kd>
        </gazebo> 

        <joint
            name="wrist_1_joint"
            type="revolute">
            <origin
            xyz="0 0 -0.071693"
            rpy="3.1416 0 2.8331" />
            <parent
            link="forearm_link" />
            <child
            link="wrist_1_link" />
            <axis
            xyz="0 0 1" />
            <limit
            lower="-3.14"
            upper="3.14"
            effort="100"
            velocity="100" />
        </joint>


        <xacro:le_arm_gripper prefix="" parent="wrist_1_link" >
            <origin xyz="0 0.009 0.059" rpy="0 0 0"/>
        </xacro:le_arm_gripper>


        <xacro:le_arm_transmission prefix=""/>

    </xacro:macro>    
</robot>