<sdf version='1.6'>
  <model name='flying_manipulator_sim'>
    <link name='arm_base_link'>
      <pose frame=''>0 0 0 0 -0 0</pose>
      <inertial>
        <pose frame=''>-0 -0.00052 -0.060933 0 -0 0</pose>
        <mass>0.23834</mass>
        <inertia>
          <ixx>0.00014646</ixx>
          <ixy>-4.6203e-05</ixy>
          <ixz>-2.9588e-12</ixz>
          <iyy>0.00021227</iyy>
          <iyz>5.2784e-06</iyz>
          <izz>0.00027887</izz>
        </inertia>
      </inertial>
      <collision name='arm_base_link_collision'>
        <pose frame=''>0 0 0 0 -0 0</pose>
        <geometry>
          <mesh>
            <scale>1 1 1</scale>
            <uri>model://flying_manipulator_sim/meshes/arm_base_link.STL</uri>
          </mesh>
        </geometry>
      </collision>
      <visual name='arm_base_link_visual'>
        <pose frame=''>0 0 0 0 -0 0</pose>
        <geometry>
          <mesh>
            <scale>1 1 1</scale>
            <uri>model://flying_manipulator_sim/meshes/arm_base_link.STL</uri>
          </mesh>
        </geometry>
      </visual>
    </link>
    <link name='arm_link_1'>
      <pose frame=''>0 -0.026 -0.0895 -1.57079 1.57079 3.14159</pose>
      <inertial>
        <pose frame=''>0.040115 -1e-06 -0.018802 0 -0 0</pose>
        <mass>0.087666</mass>
        <inertia>
          <ixx>3.7509e-05</ixx>
          <ixy>-2.1029e-09</ixy>
          <ixz>5.4309e-06</ixz>
          <iyy>3.0921e-05</iyy>
          <iyz>-3.1764e-10</iyz>
          <izz>3.1628e-05</izz>
        </inertia>
      </inertial>
      <collision name='arm_link_1_collision'>
        <pose frame=''>0 0 0 0 -0 0</pose>
        <geometry>
          <mesh>
            <scale>1 1 1</scale>
            <uri>model://flying_manipulator_sim/meshes/arm_link_1.STL</uri>
          </mesh>
        </geometry>
      </collision>
      <visual name='arm_link_1_visual'>
        <pose frame=''>0 0 0 0 -0 0</pose>
        <geometry>
          <mesh>
            <scale>1 1 1</scale>
            <uri>model://flying_manipulator_sim/meshes/arm_link_1.STL</uri>
          </mesh>
        </geometry>
      </visual>
    </link>
    <joint name='arm_joint_1' type='revolute'>
      <child>arm_link_1</child>
      <parent>arm_base_link</parent>
      <axis>
        <xyz>0 0 1</xyz>
        <limit>
          <lower>-3</lower>
          <upper>3</upper>
          <effort>10</effort>
          <velocity>10</velocity>
        </limit>
        <dynamics>
          <spring_reference>0</spring_reference>
          <spring_stiffness>0</spring_stiffness>
        </dynamics>
        <use_parent_model_frame>0</use_parent_model_frame>
      </axis>
    </joint>
    <link name='arm_link_2'>
      <pose frame=''>-0 -0 -0.161 3.14159 -7e-06 3.14159</pose>
      <inertial>
        <pose frame=''>-9.9e-05 0.002075 0.058815 0 -0 0</pose>
        <mass>0.094719</mass>
        <inertia>
          <ixx>3.2796e-05</ixx>
          <ixy>3.2548e-08</ixy>
          <ixz>-8.0921e-08</ixz>
          <iyy>4.4585e-05</iyy>
          <iyz>6.4071e-07</iyz>
          <izz>1.7843e-05</izz>
        </inertia>
      </inertial>
      <collision name='arm_link_2_collision'>
        <pose frame=''>0 0 0 0 -0 0</pose>
        <geometry>
          <mesh>
            <scale>1 1 1</scale>
            <uri>model://flying_manipulator_sim/meshes/arm_link_2.STL</uri>
          </mesh>
        </geometry>
      </collision>
      <visual name='arm_link_2_visual'>
        <pose frame=''>0 0 0 0 -0 0</pose>
        <geometry>
          <mesh>
            <scale>1 1 1</scale>
            <uri>model://flying_manipulator_sim/meshes/arm_link_2.STL</uri>
          </mesh>
        </geometry>
      </visual>
    </link>
    <joint name='arm_joint_2' type='revolute'>
      <child>arm_link_2</child>
      <parent>arm_link_1</parent>
      <axis>
        <xyz>0 0 1</xyz>
        <limit>
          <lower>-3</lower>
          <upper>3</upper>
          <effort>5</effort>
          <velocity>10</velocity>
        </limit>
        <dynamics>
          <spring_reference>0</spring_reference>
          <spring_stiffness>0</spring_stiffness>
        </dynamics>
        <use_parent_model_frame>0</use_parent_model_frame>
      </axis>
    </joint>
    <link name='arm_link_3'>
      <pose frame=''>-1e-06 0.027 -0.2415 -2.35619 1.57079 2.35619</pose>
      <inertial>
        <pose frame=''>0.039025 1e-06 0.019681 0 -0 0</pose>
        <mass>0.086986</mass>
        <inertia>
          <ixx>3.7684e-05</ixx>
          <ixy>2.1035e-09</ixy>
          <ixz>-5.3749e-06</ixz>
          <iyy>3.0528e-05</iyy>
          <iyz>-3.1693e-10</iyz>
          <izz>3.0641e-05</izz>
        </inertia>
      </inertial>
      <collision name='arm_link_3_collision'>
        <pose frame=''>0 0 0 0 -0 0</pose>
        <geometry>
          <mesh>
            <scale>1 1 1</scale>
            <uri>model://flying_manipulator_sim/meshes/arm_link_3.STL</uri>
          </mesh>
        </geometry>
      </collision>
      <visual name='arm_link_3_visual'>
        <pose frame=''>0 0 0 0 -0 0</pose>
        <geometry>
          <mesh>
            <scale>1 1 1</scale>
            <uri>model://flying_manipulator_sim/meshes/arm_link_3.STL</uri>
          </mesh>
        </geometry>
      </visual>
    </link>
    <joint name='arm_joint_3' type='revolute'>
      <child>arm_link_3</child>
      <parent>arm_link_2</parent>
      <axis>
        <xyz>0 0 -1</xyz>
        <limit>
          <lower>-3</lower>
          <upper>3</upper>
          <effort>5</effort>
          <velocity>10</velocity>
        </limit>
        <dynamics>
          <spring_reference>0</spring_reference>
          <spring_stiffness>0</spring_stiffness>
        </dynamics>
        <use_parent_model_frame>0</use_parent_model_frame>
      </axis>
    </joint>
    <link name='arm_link_4'>
      <pose frame=''>-1e-06 1e-06 -0.3115 3.14159 -7e-06 3.14159</pose>
      <inertial>
        <pose frame=''>-0.00293 -0.000205 0.009605 0 -0 0</pose>
        <mass>0.013253</mass>
        <inertia>
          <ixx>1.7076e-06</ixx>
          <ixy>7.9684e-09</ixy>
          <ixz>1.1168e-07</ixz>
          <iyy>2.333e-06</iyy>
          <iyz>-4.9095e-09</iyz>
          <izz>3.0343e-06</izz>
        </inertia>
      </inertial>
      <collision name='arm_link_4_collision'>
        <pose frame=''>0 0 0 0 -0 0</pose>
        <geometry>
          <mesh>
            <scale>1 1 1</scale>
            <uri>model://flying_manipulator_sim/meshes/arm_link_4.STL</uri>
          </mesh>
        </geometry>
      </collision>
      <visual name='arm_link_4_visual'>
        <pose frame=''>0 0 0 0 -0 0</pose>
        <geometry>
          <mesh>
            <scale>1 1 1</scale>
            <uri>model://flying_manipulator_sim/meshes/arm_link_4.STL</uri>
          </mesh>
        </geometry>
      </visual>
    </link>
    <joint name='arm_joint_4' type='revolute'>
      <child>arm_link_4</child>
      <parent>arm_link_3</parent>
      <axis>
        <xyz>0 0 1</xyz>
        <limit>
          <lower>-3</lower>
          <upper>3</upper>
          <effort>5</effort>
          <velocity>10</velocity>
        </limit>
        <dynamics>
          <spring_reference>0</spring_reference>
          <spring_stiffness>0</spring_stiffness>
        </dynamics>
        <use_parent_model_frame>0</use_parent_model_frame>
      </axis>
    </joint>

    <plugin name='joint_state' filename='libgazebo_ros_joint_state_publisher.so'>
      <robotNamespace>joint_2</robotNamespace>
      <jointName>arm_joint_2</jointName>
    </plugin>

    <plugin name='joint_controller' filename='libgazebo_ros_joint_vel_controller.so'>
      <robotNamespace>joint_2</robotNamespace>
      <jointName>arm_joint_2</jointName>
      <p_gain>0.01</p_gain>
    </plugin>
    
  </model>
</sdf>
